10 june 2021

Traceback (most recent call last):
  File "/home/user/PycharmProjects/valrBtcBot/venv/lib/python3.8/site-packages/websockets/legacy/protocol.py", line 750, in transfer_data
    message = await self.read_message()
  File "/home/user/PycharmProjects/valrBtcBot/venv/lib/python3.8/site-packages/websockets/legacy/protocol.py", line 819, in read_message
    frame = await self.read_data_frame(max_size=self.max_size)
  File "/home/user/PycharmProjects/valrBtcBot/venv/lib/python3.8/site-packages/websockets/legacy/protocol.py", line 895, in read_data_frame
    frame = await self.read_frame(max_size)
  File "/home/user/PycharmProjects/valrBtcBot/venv/lib/python3.8/site-packages/websockets/legacy/protocol.py", line 971, in read_frame
    frame = await Frame.read(
  File "/home/user/PycharmProjects/valrBtcBot/venv/lib/python3.8/site-packages/websockets/legacy/framing.py", line 55, in read
    data = await reader(2)
  File "/usr/lib/python3.8/asyncio/streams.py", line 723, in readexactly
    await self._wait_for_data('readexactly')
  File "/usr/lib/python3.8/asyncio/streams.py", line 517, in _wait_for_data
    await self._waiter
  File "/usr/lib/python3.8/asyncio/selector_events.py", line 846, in _read_ready__data_received
    data = self._sock.recv(self.max_size)
ConnectionResetError: [Errno 104] Connection reset by peer

The above exception was the direct cause of the following exception:

Traceback (most recent call last):
  File "main.py", line 40, in <module>
    loop.run_until_complete(c.run())
  File "/usr/lib/python3.8/asyncio/base_events.py", line 616, in run_until_complete
    return future.result()
  File "/home/user/PycharmProjects/valrBtcBot/venv/lib/python3.8/site-packages/valr_python/ws_client.py", line 918, in run
    async for message in ws:
  File "/home/user/PycharmProjects/valrBtcBot/venv/lib/python3.8/site-packages/websockets/legacy/protocol.py", line 356, in __aiter__
    yield await self.recv()
  File "/home/user/PycharmProjects/valrBtcBot/venv/lib/python3.8/site-packages/websockets/legacy/protocol.py", line 421, in recv
    await self.ensure_open()
  File "/home/user/PycharmProjects/valrBtcBot/venv/lib/python3.8/site-packages/websockets/legacy/protocol.py", line 726, in ensure_open
    raise self.connection_closed_exc()
websockets.exceptions.ConnectionClosedError: code = 1006 (connection closed abnormally [internal]), no reason













